2023-02-23 20:20:41,045 - Shard ID None has connected to Gateway (Session ID: 09a5e7b46c23f9339582bced40d1a418).
2023-02-23 20:20:50,941 - SansPapyrus683#4140: a.redeem card punch 15 <@441672776345190421>
2023-02-23 21:59:09,879 - Shard ID None has connected to Gateway (Session ID: b856bf249407061acebd4ef8a8f41bd2).
2023-02-23 21:59:13,927 - SansPapyrus683#4140: a.test
2023-02-23 21:59:47,775 - Shard ID None has connected to Gateway (Session ID: 5f78fcc1077aa33281304b82f41d9874).
2023-02-23 21:59:52,079 - SansPapyrus683#4140: a.test
2023-02-23 22:01:23,471 - SansPapyrus683#4140: 
2023-02-23 22:17:24,739 - Shard ID None has successfully RESUMED session 5f78fcc1077aa33281304b82f41d9874.
2023-02-23 23:38:02,495 - Shard ID None has successfully RESUMED session 5f78fcc1077aa33281304b82f41d9874.
2023-02-23 23:46:45,930 - Ignoring exception in on_command_error
Traceback (most recent call last):
  File "C:\Users\kevin\GitHub\discord-adventurers-bot\venv\lib\site-packages\discord\ext\commands\core.py", line 229, in wrapped
    ret = await coro(*args, **kwargs)
  File "C:\Users\kevin\GitHub\discord-adventurers-bot\cogs\play\pvp_temp.py", line 133, in move
    await ctx.message.delete()
  File "C:\Users\kevin\GitHub\discord-adventurers-bot\venv\lib\site-packages\discord\message.py", line 805, in delete
    await self._state.http.delete_message(self.channel.id, self.id)
  File "C:\Users\kevin\GitHub\discord-adventurers-bot\venv\lib\site-packages\discord\http.py", line 740, in request
    raise NotFound(response, data)
discord.errors.NotFound: 404 Not Found (error code: 10008): Unknown Message

The above exception was the direct cause of the following exception:

Traceback (most recent call last):
  File "C:\Users\kevin\GitHub\discord-adventurers-bot\venv\lib\site-packages\discord\client.py", line 409, in _run_event
    await coro(*args, **kwargs)
  File "C:\Users\kevin\GitHub\discord-adventurers-bot\main.py", line 120, in on_command_error
    raise error
  File "C:\Users\kevin\GitHub\discord-adventurers-bot\venv\lib\site-packages\discord\ext\commands\bot.py", line 1349, in invoke
    await ctx.command.invoke(ctx)
  File "C:\Users\kevin\GitHub\discord-adventurers-bot\venv\lib\site-packages\discord\ext\commands\core.py", line 1023, in invoke
    await injected(*ctx.args, **ctx.kwargs)  # type: ignore
  File "C:\Users\kevin\GitHub\discord-adventurers-bot\venv\lib\site-packages\discord\ext\commands\core.py", line 238, in wrapped
    raise CommandInvokeError(exc) from exc
discord.ext.commands.errors.CommandInvokeError: Command raised an exception: NotFound: 404 Not Found (error code: 10008): Unknown Message
2023-02-24 01:49:48,098 - Shard ID None has successfully RESUMED session 5f78fcc1077aa33281304b82f41d9874.
2023-02-24 03:47:24,157 - Shard ID None has successfully RESUMED session 5f78fcc1077aa33281304b82f41d9874.
2023-02-24 04:40:11,782 - Shard ID None has successfully RESUMED session 5f78fcc1077aa33281304b82f41d9874.
2023-02-24 04:52:11,162 - Shard ID None has successfully RESUMED session 5f78fcc1077aa33281304b82f41d9874.
2023-02-24 05:12:27,989 - Shard ID None has successfully RESUMED session 5f78fcc1077aa33281304b82f41d9874.
2023-02-24 05:38:57,973 - Shard ID None has successfully RESUMED session 5f78fcc1077aa33281304b82f41d9874.
2023-02-24 08:10:43,203 - Shard ID None has successfully RESUMED session 5f78fcc1077aa33281304b82f41d9874.
2023-02-24 08:57:36,892 - Shard ID None has successfully RESUMED session 5f78fcc1077aa33281304b82f41d9874.
2023-02-24 12:54:22,814 - Shard ID None has successfully RESUMED session 5f78fcc1077aa33281304b82f41d9874.
2023-02-24 15:06:47,944 - Shard ID None has successfully RESUMED session 5f78fcc1077aa33281304b82f41d9874.
2023-02-24 17:30:18,059 - Shard ID None has successfully RESUMED session 5f78fcc1077aa33281304b82f41d9874.
2023-02-24 17:55:05,505 - Shard ID None has connected to Gateway (Session ID: 895851d9da4fe00406ceac435081239c).
2023-02-24 17:56:08,952 - Shard ID None has connected to Gateway (Session ID: 753f2a162e752d52d126730d886dca34).
2023-02-25 17:26:55,460 - Shard ID None has connected to Gateway (Session ID: 2163a57bd01b920fe3009572b58c9763).
2023-02-25 17:27:24,919 - Ignoring exception in on_command_error
Traceback (most recent call last):
  File "C:\Users\xiaon\Documents\PythonProjects\Discord Bots\discord-adventurers-bot\env\lib\site-packages\discord\ext\commands\converter.py", line 1231, in _actual_conversion
    return converter(argument)
ValueError: invalid literal for int() with base 10: '<@443548823759880192>'

The above exception was the direct cause of the following exception:

Traceback (most recent call last):
  File "C:\Users\xiaon\Documents\PythonProjects\Discord Bots\discord-adventurers-bot\env\lib\site-packages\discord\client.py", line 409, in _run_event
    await coro(*args, **kwargs)
  File "c:\Users\xiaon\Documents\PythonProjects\Discord Bots\discord-adventurers-bot\main.py", line 120, in on_command_error
    raise error
  File "C:\Users\xiaon\Documents\PythonProjects\Discord Bots\discord-adventurers-bot\env\lib\site-packages\discord\ext\commands\bot.py", line 1349, in invoke
    await ctx.command.invoke(ctx)
  File "C:\Users\xiaon\Documents\PythonProjects\Discord Bots\discord-adventurers-bot\env\lib\site-packages\discord\ext\commands\core.py", line 1015, in invoke
    await self.prepare(ctx)
  File "C:\Users\xiaon\Documents\PythonProjects\Discord Bots\discord-adventurers-bot\env\lib\site-packages\discord\ext\commands\core.py", line 932, in prepare
    await self._parse_arguments(ctx)
  File "C:\Users\xiaon\Documents\PythonProjects\Discord Bots\discord-adventurers-bot\env\lib\site-packages\discord\ext\commands\hybrid.py", line 531, in _parse_arguments
    return await super()._parse_arguments(ctx)
  File "C:\Users\xiaon\Documents\PythonProjects\Discord Bots\discord-adventurers-bot\env\lib\site-packages\discord\ext\commands\core.py", line 839, in _parse_arguments
    transformed = await self.transform(ctx, param, attachments)
  File "C:\Users\xiaon\Documents\PythonProjects\Discord Bots\discord-adventurers-bot\env\lib\site-packages\discord\ext\commands\core.py", line 709, in transform
    return await run_converters(ctx, converter, argument, param)  # type: ignore
  File "C:\Users\xiaon\Documents\PythonProjects\Discord Bots\discord-adventurers-bot\env\lib\site-packages\discord\ext\commands\converter.py", line 1340, in run_converters
    return await _actual_conversion(ctx, converter, argument, param)
  File "C:\Users\xiaon\Documents\PythonProjects\Discord Bots\discord-adventurers-bot\env\lib\site-packages\discord\ext\commands\converter.py", line 1240, in _actual_conversion
    raise BadArgument(f'Converting to "{name}" failed for parameter "{param.name}".') from exc
discord.ext.commands.errors.BadArgument: Converting to "int" failed for parameter "gamble_medals".
2023-02-25 17:28:00,552 - Ignoring exception in view <Actions timeout=180.0 children=5> for item <Button style=<ButtonStyle.secondary: 2> url=None disabled=False label='Finish' emoji=None row=2>
Traceback (most recent call last):
  File "C:\Users\xiaon\Documents\PythonProjects\Discord Bots\discord-adventurers-bot\env\lib\site-packages\discord\ui\view.py", line 425, in _scheduled_task
    await item.callback(interaction)
  File "c:\Users\xiaon\Documents\PythonProjects\Discord Bots\discord-adventurers-bot\views\battle\actions.py", line 32, in finish_button
    result = self.battledata.show_finish(i.user.id)
  File "c:\Users\xiaon\Documents\PythonProjects\Discord Bots\discord-adventurers-bot\helpers\battle_temp.py", line 147, in show_finish
    energy_cost += p.deck[int(move[0])].get_energy_cost()
  File "c:\Users\xiaon\Documents\PythonProjects\Discord Bots\discord-adventurers-bot\helpers\battle_temp.py", line 20, in get_energy_cost
    return self.card["cost"]
TypeError: 'NoneType' object is not subscriptable
2023-02-25 17:29:09,117 - Shard ID None has connected to Gateway (Session ID: 6fb852d5980850baa396ddcef6974b24).
2023-02-25 17:32:41,329 - Ignoring exception in view <Actions timeout=180.0 children=5> for item <Button style=<ButtonStyle.secondary: 2> url=None disabled=False label='Finish' emoji=None row=2>
Traceback (most recent call last):
  File "C:\Users\xiaon\Documents\PythonProjects\Discord Bots\discord-adventurers-bot\env\lib\site-packages\discord\ui\view.py", line 425, in _scheduled_task
    await item.callback(interaction)
  File "c:\Users\xiaon\Documents\PythonProjects\Discord Bots\discord-adventurers-bot\views\battle\actions.py", line 32, in finish_button
    result = self.battledata.show_finish(i.user.id)
  File "c:\Users\xiaon\Documents\PythonProjects\Discord Bots\discord-adventurers-bot\helpers\battle_temp.py", line 148, in show_finish
    if not (1 <= int(move[1]) <= len(self.players)):
  File "c:\Users\xiaon\Documents\PythonProjects\Discord Bots\discord-adventurers-bot\helpers\battle_temp.py", line 20, in get_energy_cost
    print(self.cost)
AttributeError: 'Card' object has no attribute 'cost'
2023-02-25 17:33:05,976 - Shard ID None has connected to Gateway (Session ID: 0ddbca61949cbe7121e98ef9db385554).
2023-02-25 17:36:04,349 - Ignoring exception in on_command_error
Traceback (most recent call last):
  File "C:\Users\xiaon\Documents\PythonProjects\Discord Bots\discord-adventurers-bot\env\lib\site-packages\discord\ext\commands\converter.py", line 1231, in _actual_conversion
    return converter(argument)
ValueError: invalid literal for int() with base 10: '<@443548823759880192>'

The above exception was the direct cause of the following exception:

Traceback (most recent call last):
  File "C:\Users\xiaon\Documents\PythonProjects\Discord Bots\discord-adventurers-bot\env\lib\site-packages\discord\client.py", line 409, in _run_event
    await coro(*args, **kwargs)
  File "c:\Users\xiaon\Documents\PythonProjects\Discord Bots\discord-adventurers-bot\main.py", line 120, in on_command_error
    raise error
  File "C:\Users\xiaon\Documents\PythonProjects\Discord Bots\discord-adventurers-bot\env\lib\site-packages\discord\ext\commands\bot.py", line 1349, in invoke
    await ctx.command.invoke(ctx)
  File "C:\Users\xiaon\Documents\PythonProjects\Discord Bots\discord-adventurers-bot\env\lib\site-packages\discord\ext\commands\core.py", line 1015, in invoke
    await self.prepare(ctx)
  File "C:\Users\xiaon\Documents\PythonProjects\Discord Bots\discord-adventurers-bot\env\lib\site-packages\discord\ext\commands\core.py", line 932, in prepare
    await self._parse_arguments(ctx)
  File "C:\Users\xiaon\Documents\PythonProjects\Discord Bots\discord-adventurers-bot\env\lib\site-packages\discord\ext\commands\hybrid.py", line 531, in _parse_arguments
    return await super()._parse_arguments(ctx)
  File "C:\Users\xiaon\Documents\PythonProjects\Discord Bots\discord-adventurers-bot\env\lib\site-packages\discord\ext\commands\core.py", line 839, in _parse_arguments
    transformed = await self.transform(ctx, param, attachments)
  File "C:\Users\xiaon\Documents\PythonProjects\Discord Bots\discord-adventurers-bot\env\lib\site-packages\discord\ext\commands\core.py", line 709, in transform
    return await run_converters(ctx, converter, argument, param)  # type: ignore
  File "C:\Users\xiaon\Documents\PythonProjects\Discord Bots\discord-adventurers-bot\env\lib\site-packages\discord\ext\commands\converter.py", line 1340, in run_converters
    return await _actual_conversion(ctx, converter, argument, param)
  File "C:\Users\xiaon\Documents\PythonProjects\Discord Bots\discord-adventurers-bot\env\lib\site-packages\discord\ext\commands\converter.py", line 1240, in _actual_conversion
    raise BadArgument(f'Converting to "{name}" failed for parameter "{param.name}".') from exc
discord.ext.commands.errors.BadArgument: Converting to "int" failed for parameter "gamble_medals".
2023-02-25 17:37:00,015 - Ignoring exception in view <Actions timeout=180.0 children=5> for item <Button style=<ButtonStyle.secondary: 2> url=None disabled=False label='Finish' emoji=None row=2>
Traceback (most recent call last):
  File "C:\Users\xiaon\Documents\PythonProjects\Discord Bots\discord-adventurers-bot\env\lib\site-packages\discord\ui\view.py", line 425, in _scheduled_task
    await item.callback(interaction)
  File "c:\Users\xiaon\Documents\PythonProjects\Discord Bots\discord-adventurers-bot\views\battle\actions.py", line 32, in finish_button
    result = self.battledata.show_finish(i.user.id)
  File "c:\Users\xiaon\Documents\PythonProjects\Discord Bots\discord-adventurers-bot\helpers\battle_temp.py", line 151, in show_finish
    energy_cost += p.deck[int(move[0])].get_energy_cost()
  File "c:\Users\xiaon\Documents\PythonProjects\Discord Bots\discord-adventurers-bot\helpers\battle_temp.py", line 21, in get_energy_cost
    return self.card["cost"]
TypeError: 'NoneType' object is not subscriptable
2023-02-25 17:38:26,804 - Shard ID None has connected to Gateway (Session ID: 4e2f655d715605ca9facb60815fbd355).
2023-02-25 17:38:55,511 - Ignoring exception in view <Actions timeout=180.0 children=5> for item <Button style=<ButtonStyle.secondary: 2> url=None disabled=False label='Finish' emoji=None row=2>
Traceback (most recent call last):
  File "C:\Users\xiaon\Documents\PythonProjects\Discord Bots\discord-adventurers-bot\env\lib\site-packages\discord\ui\view.py", line 425, in _scheduled_task
    await item.callback(interaction)
  File "c:\Users\xiaon\Documents\PythonProjects\Discord Bots\discord-adventurers-bot\views\battle\actions.py", line 32, in finish_button
    result = self.battledata.show_finish(i.user.id)
  File "c:\Users\xiaon\Documents\PythonProjects\Discord Bots\discord-adventurers-bot\helpers\battle_temp.py", line 153, in show_finish
    energy_cost += p.deck[int(move[0])].get_energy_cost()
  File "c:\Users\xiaon\Documents\PythonProjects\Discord Bots\discord-adventurers-bot\helpers\battle_temp.py", line 21, in get_energy_cost
    return self.card["cost"]
TypeError: 'NoneType' object is not subscriptable
2023-02-25 17:39:34,207 - Shard ID None has connected to Gateway (Session ID: d79c7135c4c90112d284e0fe4d88bdf6).
2023-02-25 18:39:11,714 - Shard ID None has connected to Gateway (Session ID: f78d098549ca9f413fea1b5e07c820cf).
2023-02-25 22:02:32,583 - Shard ID None has successfully RESUMED session f78d098549ca9f413fea1b5e07c820cf.
2023-02-25 23:38:00,149 - Shard ID None has connected to Gateway (Session ID: 58745bca394113ecff55eb95408c90a1).
2023-02-25 23:41:53,854 - Ignoring exception in view <Actions timeout=180.0 children=5> for item <Button style=<ButtonStyle.secondary: 2> url=None disabled=False label='Finish' emoji=None row=2>
Traceback (most recent call last):
  File "C:\Users\xiaon\Documents\PythonProjects\Discord Bots\discord-adventurers-bot\env\lib\site-packages\discord\ui\view.py", line 425, in _scheduled_task
    await item.callback(interaction)
  File "c:\Users\xiaon\Documents\PythonProjects\Discord Bots\discord-adventurers-bot\views\battle\actions.py", line 32, in finish_button
    result = self.battledata.show_finish(i.user.id)
  File "c:\Users\xiaon\Documents\PythonProjects\Discord Bots\discord-adventurers-bot\helpers\battle_temp.py", line 153, in show_finish
    target = self.players[move[1]]
TypeError: list indices must be integers or slices, not str
2023-02-25 23:42:59,586 - Shard ID None has connected to Gateway (Session ID: a9ab4442033b620c90ab4bd9f6fa29fe).
2023-02-25 23:43:36,965 - Ignoring exception in view <Actions timeout=180.0 children=5> for item <Button style=<ButtonStyle.secondary: 2> url=None disabled=False label='Finish' emoji=None row=2>
Traceback (most recent call last):
  File "C:\Users\xiaon\Documents\PythonProjects\Discord Bots\discord-adventurers-bot\env\lib\site-packages\discord\ui\view.py", line 425, in _scheduled_task
    await item.callback(interaction)
  File "c:\Users\xiaon\Documents\PythonProjects\Discord Bots\discord-adventurers-bot\views\battle\actions.py", line 32, in finish_button
    result = self.battledata.show_finish(i.user.id)
  File "c:\Users\xiaon\Documents\PythonProjects\Discord Bots\discord-adventurers-bot\helpers\battle_temp.py", line 153, in show_finish
    target = self.players[move[1]]
TypeError: list indices must be integers or slices, not str
2023-02-25 23:44:01,345 - Shard ID None has connected to Gateway (Session ID: 33897f6b767813fc1174633976a052fa).
2023-02-25 23:44:33,717 - Ignoring exception in view <Actions timeout=180.0 children=5> for item <Button style=<ButtonStyle.secondary: 2> url=None disabled=False label='Finish' emoji=None row=2>
Traceback (most recent call last):
  File "C:\Users\xiaon\Documents\PythonProjects\Discord Bots\discord-adventurers-bot\env\lib\site-packages\discord\ui\view.py", line 425, in _scheduled_task
    await item.callback(interaction)
  File "c:\Users\xiaon\Documents\PythonProjects\Discord Bots\discord-adventurers-bot\views\battle\actions.py", line 32, in finish_button
    result = self.battledata.show_finish(i.user.id)
  File "c:\Users\xiaon\Documents\PythonProjects\Discord Bots\discord-adventurers-bot\helpers\battle_temp.py", line 153, in show_finish
    target = self.players[int(move[1])]
IndexError: list index out of range
2023-02-25 23:44:58,994 - Shard ID None has connected to Gateway (Session ID: b3fd857429a0c97bc66091fc9506e646).
2023-02-25 23:46:57,457 - Ignoring exception in view <Actions timeout=180.0 children=5> for item <Button style=<ButtonStyle.secondary: 2> url=None disabled=False label='Finish' emoji=None row=2>
Traceback (most recent call last):
  File "C:\Users\xiaon\Documents\PythonProjects\Discord Bots\discord-adventurers-bot\env\lib\site-packages\discord\ui\view.py", line 425, in _scheduled_task
    await item.callback(interaction)
  File "c:\Users\xiaon\Documents\PythonProjects\Discord Bots\discord-adventurers-bot\views\battle\actions.py", line 32, in finish_button
    result = self.battledata.show_finish(i.user.id)
  File "c:\Users\xiaon\Documents\PythonProjects\Discord Bots\discord-adventurers-bot\helpers\battle_temp.py", line 159, in show_finish
    card.use(target=p)
  File "c:\Users\xiaon\Documents\PythonProjects\Discord Bots\discord-adventurers-bot\helpers\card.py", line 43, in use
    self.crit_use()
TypeError: Card.crit_use() missing 1 required positional argument: 'target'
2023-02-25 23:51:01,175 - Shard ID None has connected to Gateway (Session ID: ac18d8b1282c1602308c4bc8878b3ca8).
2023-02-25 23:52:06,349 - Ignoring exception in view <Actions timeout=180.0 children=5> for item <Button style=<ButtonStyle.secondary: 2> url=None disabled=False label='Finish' emoji=None row=2>
Traceback (most recent call last):
  File "C:\Users\xiaon\Documents\PythonProjects\Discord Bots\discord-adventurers-bot\env\lib\site-packages\discord\ui\view.py", line 425, in _scheduled_task
    await item.callback(interaction)
  File "c:\Users\xiaon\Documents\PythonProjects\Discord Bots\discord-adventurers-bot\views\battle\actions.py", line 32, in finish_button
    result = self.battledata.show_finish(i.user.id)
  File "c:\Users\xiaon\Documents\PythonProjects\Discord Bots\discord-adventurers-bot\helpers\battle_temp.py", line 160, in show_finish
    use_card(target=p)
TypeError: 'Card' object is not callable
2023-02-25 23:52:58,723 - Shard ID None has connected to Gateway (Session ID: d1b77786e5853202cff40c3d2867c25d).
2023-02-25 23:53:23,905 - Ignoring exception in view <Actions timeout=180.0 children=5> for item <Button style=<ButtonStyle.secondary: 2> url=None disabled=False label='Finish' emoji=None row=2>
Traceback (most recent call last):
  File "C:\Users\xiaon\Documents\PythonProjects\Discord Bots\discord-adventurers-bot\env\lib\site-packages\discord\ui\view.py", line 425, in _scheduled_task
    await item.callback(interaction)
  File "c:\Users\xiaon\Documents\PythonProjects\Discord Bots\discord-adventurers-bot\views\battle\actions.py", line 32, in finish_button
    result = self.battledata.show_finish(i.user.id)
  File "c:\Users\xiaon\Documents\PythonProjects\Discord Bots\discord-adventurers-bot\helpers\battle_temp.py", line 160, in show_finish
    use_card(target=p)
TypeError: 'Card' object is not callable
2023-02-25 23:55:38,290 - Shard ID None has connected to Gateway (Session ID: 2905430fc6bd198296ce3dd30b8e5bec).
2023-02-25 23:58:44,737 - Shard ID None has connected to Gateway (Session ID: 8f13648714e8630a5536e55b352cf41b).
2023-02-25 23:59:50,957 - Ignoring exception in view <Actions timeout=180.0 children=5> for item <Button style=<ButtonStyle.secondary: 2> url=None disabled=False label='Finish' emoji=None row=2>
Traceback (most recent call last):
  File "C:\Users\xiaon\Documents\PythonProjects\Discord Bots\discord-adventurers-bot\env\lib\site-packages\discord\ui\view.py", line 425, in _scheduled_task
    await item.callback(interaction)
  File "c:\Users\xiaon\Documents\PythonProjects\Discord Bots\discord-adventurers-bot\views\battle\actions.py", line 32, in finish_button
    result = self.battledata.show_finish(i.user.id)
  File "c:\Users\xiaon\Documents\PythonProjects\Discord Bots\discord-adventurers-bot\helpers\battle_temp.py", line 154, in show_finish
    target = self.players[int(move[1])-1]
ValueError: invalid literal for int() with base 10: 'l'
2023-02-26 00:01:35,212 - Shard ID None has connected to Gateway (Session ID: 106fef1aa54610ecbdef77fc63919f97).
2023-02-26 00:02:22,150 - Ignoring exception in view <Actions timeout=180.0 children=5> for item <Button style=<ButtonStyle.secondary: 2> url=None disabled=False label='Finish' emoji=None row=2>
Traceback (most recent call last):
  File "C:\Users\xiaon\Documents\PythonProjects\Discord Bots\discord-adventurers-bot\env\lib\site-packages\discord\ui\view.py", line 425, in _scheduled_task
    await item.callback(interaction)
  File "c:\Users\xiaon\Documents\PythonProjects\Discord Bots\discord-adventurers-bot\views\battle\actions.py", line 32, in finish_button
    result = self.battledata.show_finish(i.user.id)
  File "c:\Users\xiaon\Documents\PythonProjects\Discord Bots\discord-adventurers-bot\helpers\battle_temp.py", line 154, in show_finish
    target = self.players[int(move[1])-1]
ValueError: invalid literal for int() with base 10: 'l'
2023-02-26 00:03:52,951 - Shard ID None has connected to Gateway (Session ID: 78e2fc37f399786d096b81ca9b45f3fe).
2023-02-26 00:11:58,578 - Shard ID None has connected to Gateway (Session ID: 1a8a309dc1129c2c3e824036ef940015).
2023-02-26 00:21:26,541 - Shard ID None has connected to Gateway (Session ID: 9d5f44584baf1bef303d5584f4eac79c).
2023-02-26 00:21:52,807 - Ignoring exception in on_command_error
Traceback (most recent call last):
  File "C:\Users\xiaon\Documents\PythonProjects\Discord Bots\discord-adventurers-bot\env\lib\site-packages\discord\ext\commands\core.py", line 229, in wrapped
    ret = await coro(*args, **kwargs)
  File "c:\Users\xiaon\Documents\PythonProjects\Discord Bots\discord-adventurers-bot\cogs\play\pvp_temp.py", line 87, in battle2
    for card in player.deck:
TypeError: 'NoneType' object is not iterable

The above exception was the direct cause of the following exception:

Traceback (most recent call last):
  File "C:\Users\xiaon\Documents\PythonProjects\Discord Bots\discord-adventurers-bot\env\lib\site-packages\discord\client.py", line 409, in _run_event
    await coro(*args, **kwargs)
  File "c:\Users\xiaon\Documents\PythonProjects\Discord Bots\discord-adventurers-bot\main.py", line 120, in on_command_error
    raise error
  File "C:\Users\xiaon\Documents\PythonProjects\Discord Bots\discord-adventurers-bot\env\lib\site-packages\discord\ext\commands\bot.py", line 1349, in invoke
    await ctx.command.invoke(ctx)
  File "C:\Users\xiaon\Documents\PythonProjects\Discord Bots\discord-adventurers-bot\env\lib\site-packages\discord\ext\commands\core.py", line 1023, in invoke
    await injected(*ctx.args, **ctx.kwargs)  # type: ignore
  File "C:\Users\xiaon\Documents\PythonProjects\Discord Bots\discord-adventurers-bot\env\lib\site-packages\discord\ext\commands\core.py", line 238, in wrapped
    raise CommandInvokeError(exc) from exc
discord.ext.commands.errors.CommandInvokeError: Command raised an exception: TypeError: 'NoneType' object is not iterable
2023-02-26 00:23:04,633 - Shard ID None has connected to Gateway (Session ID: a107856e077665e6a650b281924f40b6).
2023-02-26 00:28:17,054 - Shard ID None has connected to Gateway (Session ID: b2ccc11e956a1025ef1a26c211f8fb3f).
2023-02-26 00:29:21,511 - Shard ID None has connected to Gateway (Session ID: 22709ce5639605799c93f0a5b23d9efa).
2023-02-26 00:33:52,147 - Shard ID None has connected to Gateway (Session ID: eca926c98219e00aa69293d80804ddd4).
